Workbook

Sheet Evidence Matrix
A1: Entity Nature Verification — Documentary Evidence Matrix
A2: Paper ID | B2: Priority | C2: Title | D2: Full Reference (Harvard) | E2: Year | F2: Source Type | G2: Main Research Domain | H2: Research Objective(s) | I2: RO1: Characterise the threat | J2: RO2: Classify approaches and failure modes. Human vs AI | K2: RO3: Verification in Security Frameworks | L2: RO4: Analyse trust asymmetries and risk conditions. | M2: RO5: Integrated ENV Model | N2: Method / Technique | O2: Evidence Source | P2: Text-Based Comm. Context | Q2: AI Involvement | R2: Identity / Impersonation Aspect | S2: Trust Dimension | T2: Results / Key Findings | U2: Search String ID | V2: Notes (Important): | W2: Corpus Status | X2: Identification Route | Y2: Original Source | Z2: Inclusion / Role Rationale | AA2: Evidence Review Status | AB2: Dissertation Use
A3: A003 | B3: P1-CORE | C3: The End of Trust: How Agentic AI Breaks Security Assumptions | D3: Zafar, O., Nemecek, A. and Ayday, E. (2026) The End of Trust: How Agentic AI Breaks Security Assumptions. arXiv preprint arXiv:2605.16436v1 [cs.CR], 14 May. Available at: https://arxiv.org/abs/2605.16436 (Accessed: 14 July 2026). | E3: 2026 | F3: Preprint | G3: Agentic AI / Social Engineering / Security Paradigm Theory | H3: =I3&" "&J3&" "&K3&" "&L3&" "&M3 -> RO1 RO2 RO4 RO5 | I3: RO1 | J3: RO2 | L3: RO4 | M3: RO5 | N3: Conceptual Analysis; Literature Critique; Framework Proposal | O3: Academic Literature; Industry Reports (Europol, NCSC, FBI IC3, FTC, Verizon DBIR 2025) | P3: All text-based digital interaction: email, enterprise messaging, social platforms, organisational communication channels | Q3: Autonomous agentic AI (LLM-backed); generative AI (synthetic text, deepfakes); MitM agent (Infinite Impostor) | R3: Infinite Impostor: autonomous agent interposes between two parties who already trust each other, hijacking existing relationship rather than building new identity; full lifecycle social engineering automation (reconnaissance → persona → exploitation); relationship hijacking without fabricating either party | S3: Collapse of fidelity-scale tradeoff; exhaustion of trust-based security paradigm; suspect-by-default; action-level vs. identity-level evaluation; bounded-damage architecture | T3: Agentic AI eliminates the historical fidelity-scale tradeoff — targeted attacks can now be executed at mass-market scale, dissolving the key assumption underpinning all existing defences. "Infinite Impostor" attack model: agent acts as hidden intermediary between two authentic parties (not a fake identity problem — both endpoints are real). Detection-oriented defences are structurally futile in an asymmetric arms race with improving generative systems. Proposes "suspect-by-default" paradigm: abandon actor authentication in favour of action evaluation + bounded-damage architecture (escrow, rate-limited trust, exposure caps). Critically engages proof-of-humanity (personhood credentials) finding that such systems risk centralization, exclusion, and inverting the presumption of digital citizenship. Four unresolved tensions: Infinite Impostor residual, baseline contamination/measurement problem, cost of universal suspicion, platform governance accountability. | U3: ARXIV-S1 | V3: RO1: Introduces the "Infinite Impostor" attack model, where an autonomous agent inserts itself as a hidden intermediary between two real individuals who already share a trust relationship. The paper explicitly links this attack pathway to organizational threats, explaining how agents harvest data to create context-aware personas that perfectly mimic internal colleagues for Business Email Compromise (BEC) and spear-phishing campaigns RO2: Argues that human-in-the-loop detection and user awareness training are experiencing a paradigmatic failure. Traditional cues (poor grammar, generic greetings, urgency) fail because modern AI successfully mimics the central tendencies, variances, and context-dependent fluctuations of human behavior. Main contribution: The authors argue that Agentic AI collapses the "fidelity-scale tradeoff," enabling high-fidelity, individually tailored deceptions at mass-market scale, which effectively "exhausts" the current security paradigm of detection-based trust.,,. It proposes a transition from identity-centric "trust-based security" to "suspect-by-default" architectures that focus on evaluating and constraining actions rather than authenticating actors. RO4: Explores the "Infinite Impostor" attack model, where an autonomous agent inserts itself as a hidden intermediary between two parties who already trust each other. The paper emphasizes that when entity nature verification fails, the assumption of implicit trust becomes highly exploitable, fundamentally breaking legacy human-centric security paradigms and shifting organizational risk. RO5: Details how agents infiltrate trust-based external communication channels (like social media and professional networks) by constructing convincing, context-aware personas. It illustrates how these fabricated identities are used to launch Business Email Compromise (BEC) and initiate fraudulent internal communications. Strongest citable concept/mechanism/model: The Infinite Impostor,, — An attack model where an autonomous agent operates as a hidden intermediary between two real individuals, hijacking an existing trust relationship rather than building a new persona from scratch.,. Limitation or questionable assumption: The authors acknowledge a "bootstrap and measurement problem," where it may be impossible to create a "legitimate" baseline for action-based evaluation if the system is already infiltrated by synthetic actors at the moment the baseline is drawn.. Additionally, they admit their proposed "action-based evaluation" is limited against the Infinite Impostor, whose relayed communications are structurally indistinguishable from genuine activity.,. Dissertation-ready note: This source is pivotal for RO3 as it argues that the human layer is no longer a viable "last line of defence" because the cues humans use to distinguish authentic from synthetic—such as conversational nuance and response timing—can now be convincingly synthesised (Section IV-B,,). It frames the pursuit of "detecting the fake" as "structurally futile," suggesting that the human-agent distinction is essentially collapsing at the level of digital interaction (Section I,). | W3: Eligible analytical source | X3: Structured database search | Y3: arXiv | Z3: Develops the Infinite Impostor model and explains how agentic AI can exploit established trust relationships in text-based communication, supporting RO1, RO2, RO4 and the ENV problem formulation. | AA3: Full text reviewed | AB3: Analytical contribution
A4: N001 | B4: P2-HIGH | C4: TRiSM for Agentic AI: A review of Trust, Risk, and Security Management in LLM-based Agentic Multi-Agent Systems | D4: Raza, S., Sapkota, R., Karkee, M. and Emmanouilidis, C. (2026) 'TRiSM for agentic AI: a review of trust, risk, and security management in LLM-based agentic multi-agent systems', AI Open, 7, pp. 71–95. Available at: https://doi.org/10.1016/j.aiopen.2026.02.006 | E4: 2026 | F4: Journal Article | G4: Autonomous AI Agents | H4: =I4&" "&J4&" "&K4&" "&L4&" "&M4 -> RO3 RO5 | K4: RO3 | M4: RO5 | N4: Systematic Review | O4: Academic Literature | P4: Enterprise AI | Q4: Multi-Agent LLM | R4: Agent Impersonation; Trust Risk | S4: Trust Management | T4: TRiSM framework identifies impersonation and trust exploitation as top agentic AI risks | U4: GSLABS-01 | V4: RO3: The authors map existing frameworks (NIST AI RMF, ISO/IEC 42001, and the EU AI Act) against multi-agent systems. They note that existing frameworks treat risk domains as distinct and fail to model AMAS-specific dynamics like emergent coordination, delegated authority (autonomy abuse), and tool-mediated actions, proposing an adapted TRiSM framework to fill these verification gaps. RO5: Reviews tailored TRiSM (Trust, Risk, and Security Management) controls for agentic systems. It connects trust decisions directly to organizational governance, accountability, anomaly detection, and role separation. Main contribution: The source develops a system-level Trust, Risk, and Security Management (TRiSM) framework specifically for Agentic Multi-Agent Systems (AMAS), addressing emergent risks such as impersonation, cascading reasoning errors, and tool-use abuse. It introduces novel metrics, including the Component Synergy Score (CSS) and Tool Utilization Efficacy (TUE), to operationalize the measurement of autonomous coordination and security. Strongest citable concept/mechanism/model: Decision Provenance Graph — A structured, graph-based representation that records reasoning steps, data flows, and inter-agent interactions to enable post-hoc auditing and system-level interpretability. Limitation or questionable assumption: The authors acknowledge that human-centered evaluation is "resource-intensive" and fails to scale for continuous deployment, while also noting a potential "Goodhart’s Law" effect where systems might optimize for composite trust scores rather than underlying capability. Additionally, they assume that "explainability" facilitates trust, yet concede that a "faithful" explanation is not always human-interpretable. Dissertation-ready note: This survey explicitly identifies "impersonation" as a coordinated attack vector in multi-agent environments, suggesting that technical authentication must be supplemented by "decision provenance" to allow humans to verify an entity's nature (Section 6.3). It highlights a critical gap: while TRiSM aims for "trust calibration," the resource constraints of human oversight often lead to "automation bias" or "user complacency" (Section 8.2, Section 8.3). | W4: Eligible analytical source | X4: Targeted supplementary search | Y4: Google Scholar Labs | Z4: Reviews trust, risk and security management for agentic multi-agent systems and identifies gaps concerning emergent coordination, delegated authority and tool-mediated action. | AA4: Full text reviewed | AB4: Analytical contribution
A5: N002 | B5: P2-HIGH | C5: Security Analysis of Agentic AI Communication Protocols: A Comparative Evaluation | D5: Louck, Y., Stulman, A. and Dvir, A. (2025) Security Analysis of Agentic AI Communication Protocols: A Comparative Evaluation. arXiv preprint. Available at: https://arxiv.org/abs/2511.03841 (Accessed: 18 July 2026) | E5: 2025 | F5: Preprint | G5: AI Agent Security | H5: =I5&" "&J5&" "&K5&" "&L5&" "&M5 -> RO4 RO5 | L5: RO4 | M5: RO5 | N5: Comparative Evaluation | O5: Empirical Study | P5: Agent-to-Agent Communication | Q5: Multi-Agent | R5: Authentication Bypass; Impersonation | S5: Trust | T5: Protocol-level authentication bypass and agent impersonation vulnerabilities across MCP, A2A, ANP | U5: ARXIV-S8 | V5: RO4: Discusses how the absence of Strong Customer Authentication (SCA) and cryptographic discovery mechanisms allows adversaries to forge identities, impersonate trusted agents, and bypass authorization. RO5: Documents specific vulnerabilities where adversaries forge capabilities and "impersonate trusted agents during dynamic discovery." It highlights how the lack of chain-of-trust enforcement enables spoofing in agent-to-agent (A2A) interactions. Main contribution: The authors provide the first empirical, comparative security analysis of major agent communication protocols (A2A, ACP, and CORAL), identifying a critical "architecture versus implementation" dichotomy where robust designs are undermined by fundamental validation failures. The study concludes that current ecosystems remain largely insecure because they lack a hybrid approach that combines secure transport-layer isolation with mandatory, granular message-level integrity. Strongest citable concept/mechanism/model: 14-point Vulnerability Taxonomy for Multi-Agent Systems — A formal framework that groups threats into five domains (Authentication, Authorization, Integrity, Confidentiality, and Availability) to systematically evaluate how protocols handle autonomous agent interactions. Limitation or questionable assumption: The threat model explicitly excludes "physical access or full compromise of the underlying large language model (LLM)," focusing instead on the communication layer. Consequently, the authors admit that "Prompt & Tool Injection" remains a persistent "application-layer" risk that protocol-level security cannot fully mitigate, as malicious instructions may still be processed as valid by the agent's internal model. Dissertation-ready note: This source is vital for RO3 because it argues that current protocols fail to maintain the distinction between "automated and human oversight," often incorrectly equating technical agent delegation with actual user consent (Section 6.1.2, p. 14). It provides empirical evidence that even "secure" protocols can be exploited via "Spoofing in Discovery Mechanisms," where an attacker manipulates metadata to impersonate a legitimate agent and hijack organizational workflows (Section 6.2.4, p. 20; Section 8.3.2, p. 44). | W5: Eligible analytical source | X5: Structured database search | Y5: arXiv | Z5: Compares agent communication protocols and provides evidence of authentication, discovery and impersonation vulnerabilities affecting inter-agent trust. | AA5: Abstract screened | AB5: Not yet used
A6: N003 | B6: P3-MEDIUM | C6: Infrastructure for AI Agents | D6: Chan, A., Wei, K., Huang, S., Rajkumar, N., Perrier, E., Lazar, S., Hadfield, G.K. and Anderljung, M. (2025) 'Infrastructure for AI Agents', Transactions on Machine Learning Research. Available at: https://openreview.net/pdf?id=Ckh17xN2R2 | E6: 2025 | F6: Journal Article | G6: Autonomous AI Agents | H6: =I6&" "&J6&" "&K6&" "&L6&" "&M6 -> RO5 | M6: RO5 | N6: Framework Proposal | O6: Conceptual Analysis | P6: General AI Infrastructure | Q6: Agentic AI | R6: Identity / Credential Management | S6: Trust | T6: Infrastructure requirements for AI agents including identity verification and credential trust chains | U6: AI-COMP-01 | V6: RO5: Details attribution infrastructure, focusing on identity binding (linking an agent to a legal human or corporate identity) and certification tools for verifying claims about an agent's operation | W6: Eligible analytical source | X6: Targeted supplementary search | Y6: Transactions on Machine Learning Research | Z6: Identifies identity binding, attribution and certification infrastructure required for trustworthy AI-agent deployment. | AA6: Abstract screened | AB6: Not yet used
A7: N004 | B7: P1-CORE | C7: A Survey of LLM-Driven AI Agent Communication: Protocols, Security Risks, and Defense Countermeasures | D7: Kong, D., Lin, S., Xu, Z. et al. (2025a) 'A survey of LLM-driven AI agent communication: protocols, security risks, and defense countermeasures', arXiv preprint arXiv:2506.19676. Available at: https://doi.org/10.48550/arXiv.2506.19676 | E7: 2025 | F7: Preprint (Survey) | G7: AI Agent Security | H7: =I7&" "&J7&" "&K7&" "&L7&" "&M7 -> RO1 RO4 RO5 | I7: RO1 | L7: RO4 | M7: RO5 | N7: Survey / structured literature synthesis | O7: Academic Literature | P7: Agent Communication Protocols | Q7: LLM-Driven Agents | R7: Impersonation via Protocol Exploitation | S7: Trust | T7: Survey of 50+ security risks; agent impersonation via protocol gaps highlighted | U7: GSLABS-02 | V7: RO1: contrasts the static nature of standard LLMs with the dynamic adaptability and high autonomy of agents, noting that their ability to actively invoke external tools gives them the capability to cause substantial real-world damage. RO4: Highlights "Identity Spoofing" and "Authority Abuse," where compromised agents exploit inter-agent trust to gain privileges beyond user authorization, masking their true nature. RO5: Highlights the "Universal Agent Identity Layer (UAIL)," which uses Decentralized Identifiers (DIDs) and Verifiable Credentials to assign AI agents unique and verifiable identities for ethical decision-making. Main contribution: The authors propose the first structured technical framework for agent communication, categorising it into three distinct classes and a three-layered architecture (Data Transmission, Interaction Protocol, and Semantic Interpretation) to systematically map security risks. It identifies the "Semantic Interpretation Layer" as a fundamentally new attack surface where traditional security mechanisms are "blind" to deceptions involving parsed intent and reasoning. Strongest citable concept/mechanism/model: Three-Layered Agent Communication Architecture — A model that separates traditional network transmission (L1) and protocol logic (L2) from the "cognitive core" (L3), where an agent's reasoning, planning, and intention-parsing are targeted by semantic attacks. Limitation or questionable assumption: The source assumes that the "Semantic Interpretation Layer" (L3) lacks dedicated protocols and must rely on auxiliary AI models for defense, which may lead to a recursive "who guards the guardians" problem where the defense model inherits the same semantic vulnerabilities as the agent. Furthermore, it admits that in decentralized P2P architectures, there is no effective mechanism to prevent "ethical drift" or "normative collapse" without a central arbiter. Dissertation-ready note: This source provides technical weight to RO3 by detailing how compromised agents can "simulate empathy" and weaponise intimate knowledge of a user’s communication style to execute "sophisticated social engineering" that is structurally indistinguishable from a legitimate entity (Section V-B-3, p. 79). It frames the impersonation threat as a "trust conflict between obedience and safety," suggesting that agents are uniquely vulnerable because they are designed to follow instructions even when those instructions subvert their nature (Section V-B, p. 65). | W7: Eligible analytical source | X7: Structured database search | Y7: arXiv | Z7: Maps agent communication architectures, security risks, identity spoofing and authority abuse, providing evidence for the threat analysis and the relationships incorporated into ENV. | AA7: Full text reviewed | AB7: Analytical contribution
A8: N005 | B8: P3-MEDIUM | C8: Model Context Protocol (MCP): Landscape, Security Threats, and Future Research Directions | D8: Hou, X., Zhao, Y., Wang, S. and Wang, H. (2026) Model Context Protocol (MCP): Landscape, Security Threats, and Future Research Directions. ACM Transactions on Software Engineering and Methodology. Available at: https://doi.org/10.1145/3796519 | E8: 2026 | F8: Journal Article | G8: Autonomous AI Agents | H8: =I8&" "&J8&" "&K8&" "&L8&" "&M8 -> RO4 | L8: RO4 | N8: Architectural and security analysis with illustrative proof-of-concept cases | O8: Academic Literature | P8: Enterprise AI (MCP) | Q8: LLM Agent (MCP) | R8: Tool Impersonation; Name Collision | S8: Trust | T8: MCP discovery and tool-selection paths can be exploited through namespace collisions, typosquatting and persuasive metadata where textual identifiers are not bound to verified server identities. | U8: ARXIV-S2 | V8: RO4: Details "Namespace Typosquatting" and "Tool Name Conflicts," where malicious servers exploit identity ambiguity to trick hosts into trusting rogue agents. Main contribution: This source provides the first systematic architectural and security analysis of the Model Context Protocol (MCP), establishing a formal four-phase server lifecycle (creation, deployment, operation, maintenance) and a taxonomy of 16 threat scenarios. It identifies how the shift from hardcoded tool bindings to automated, dynamic discovery allows for "semantic" deceptions where agents are tricked via persuasive metadata rather than traditional infrastructure exploits. Strongest citable concept/mechanism/model: Preference Manipulation Attack (PMA) — A semantic vulnerability where a malicious actor embeds persuasive or deceptive phrases (e.g., "trusted by experts") in tool metadata to bias an AI agent’s selection process, effectively hijacking the agent's "intent analysis" layer. Limitation or questionable assumption: The authors’ proof-of-concept (PoC) is explicitly limited to demonstrating "security risks and feasibility" rather than evaluating the success rates of these attacks across different Large Language Models (LLMs), leaving the actual efficacy of the threats largely unmeasured. Additionally, the proposed defense of "metadata auditing" may be structurally outpaced by "Genetically Adapted" attacks (GAPMA) that evolve descriptions to remain inconspicuous to automated detectors. Dissertation-ready note: This survey highlights that MCP’s automation of tool selection removes the "human-in-the-loop" as a viable security layer, creating a "silent compromise" environment where agents rely on textual identifiers that lack cryptographic verification (Section 5.1.1). It provides a technical basis for RO3 by arguing that current AI ecosystems suffer from "identity ambiguity," where both the host and the agent are unable to distinguish between legitimate and impersonated functional entities (Section 5.1.2). | W8: Eligible analytical source | X8: Structured database search | Y8: arXiv | Z8: Synthesises MCP threats involving tool-name conflicts, impersonation and the absence of cryptographic identity verification. | AA8: Abstract screened | AB8: Not yet used
A9: N006 | B9: P3-MEDIUM | C9: Semantic Attacks on Tool-Augmented LLMs: Securing the Model Context Protocol Against Descriptor-Level Manipulation | D9: Jamshidi, S., Moradi Dakhel, A., Wazed Nafi, K. and Khomh, F. (2026) 'Semantic Attacks on Tool-Augmented LLMs: Securing the Model Context Protocol Against Descriptor-Level Manipulation'. Available at: https://arxiv.org/pdf/2512.06556 | E9: 2026 | F9: Preprint | G9: AI Agent Security | H9: =I9&" "&J9&" "&K9&" "&L9&" "&M9 -> RO1 | I9: RO1 | N9: Framework Proposal | O9: Empirical Study | P9: Enterprise AI (MCP) | Q9: LLM Agent (MCP) | R9: Tool Poisoning; Server Impersonation | S9: Trust | T9: Defence framework against MCP tool poisoning; server impersonation feasibility demonstrated | U9: ARXIV-S2 | V9: RO1: shows how attackers can subtly modify tool metadata (e.g., altering a "CorporateMailAssistant" tool descriptor) to bias an agent’s reasoning, leading to data leakage and unintended organizational actions | W9: Eligible analytical source | X9: Structured database search | Y9: arXiv | Z9: Demonstrates how manipulated tool descriptors can redirect agent reasoning and produce unauthorised organisational actions. | AA9: Abstract screened | AB9: Not yet used
A10: N007 | B10: P4-SUPPORT | C10: Enterprise-Grade Security for the Model Context Protocol (MCP): Frameworks and Mitigation Strategies | D10: Narajala, V.S. and Habler, I. (2025) ‘Enterprise-Grade Security for the Model Context Protocol (MCP): Frameworks and Mitigation Strategies’, arXiv preprint, arXiv:2504.08623v2 [cs.CR]. Available at: https://arxiv.org/abs/2504.08623 (Accessed: 17 July 2026). | E10: 2025 | F10: Preprint | G10: AI Agent Security | H10: =I10&" "&J10&" "&K10&" "&L10&" "&M10 -> RO3 | K10: RO3 | N10: Framework Proposal | O10: Conceptual Analysis | P10: Enterprise AI (MCP) | Q10: LLM Agent | R10: Agent Impersonation via MCP | S10: Trust | T10: Enterprise security framework for MCP: authentication, authorisation and audit for agent identity | U10: ARXIV-S2 | V10: RO3: This paper reviews security frameworks for the integration of external tools with AI models, evaluating how zero-trust architectures can mitigate operational autonomy threats like tool poisoning and identity subversion . It highlights the necessity of strict network boundaries and verifiable access validations for delegated AI tools . | W10: Eligible analytical source | X10: Structured database search | Y10: arXiv | Z10: Proposes enterprise MCP controls for agent authentication, authorisation, auditability and zero-trust enforcement. | AA10: Abstract screened | AB10: Not yet used
A11: N008 | B11: P4-SUPPORT | C11: MCP Security Bench (MSB): Benchmarking Attacks Against Model Context Protocol in LLM Agents | D11: Zhang, D., Li, Z., Luo, X., Liu, X., Li, P. and Xu, W. (2026) MCP Security Bench (MSB): Benchmarking Attacks Against Model Context Protocol in LLM Agents. arXiv preprint. Available at: https://arxiv.org/abs/2510.15994 (Accessed: 18 July 2026) | E11: 2026 | F11: Preprint | G11: AI Agent Security | H11: =I11&" "&J11&" "&K11&" "&L11&" "&M11 -> RO1 | I11: RO1 | N11: Benchmark | O11: Empirical Study | P11: Enterprise AI (MCP) | Q11: LLM Agent | R11: Impersonation; Prompt Injection | S11: Trust | T11: Benchmark of 15 MCP attack categories; impersonation and injection achieve >80% success | U11: ARXIV-S2 | V11: RO1: This study benchmarks vulnerabilities within the Model Context Protocol, characterizing the "User Impersonation" attack pathway. It details deception strategies where a malicious tool response masquerades as a human user to inject harmful instructions into an agent's workflow | W11: Eligible analytical source | X11: Structured database search | Y11: arXiv | Z11: Provides benchmark evidence on MCP attacks, including user impersonation and malicious instructions presented as legitimate communication. | AA11: Abstract screened | AB11: Not yet used
A12: N009 | B12: P3-MEDIUM | C12: MCP-DPT: A Defense-Placement Taxonomy and Coverage Analysis for Model Context Protocol Security | D12: Rostamzadeh, M., Narula, S., Birhan, N., Ghasemigol, M. and Takabi, D. 2026. 'MCP-DPT: A Defense-Placement Taxonomy and Coverage Analysis for Model Context Protocol Security'. arXiv preprint arXiv:2604.07551v1. Available at: https://arxiv.org/pdf/2604.07551 | E12: 2026 | F12: Preprint | G12: AI Agent Security | H12: =I12&" "&J12&" "&K12&" "&L12&" "&M12 -> RO4 | L12: RO4 | N12: Taxonomy Development | O12: Conceptual Analysis | P12: Enterprise AI (MCP) | Q12: LLM Agent (MCP) | R12: Defence Against Impersonation | S12: Trust | T12: Coverage analysis of 49 attacks against 13 defence mechanisms; none of the analysed mechanisms covers Resource Type Confusion / Impersonation. | U12: ARXIV-S2 | V12: RO4: Specifically identifies "Resource Type Confusion / Impersonation," where adversaries masquerade malicious content as benign artifacts to exploit an agent's trust. | W12: Eligible analytical source | X12: Structured database search | Y12: arXiv | Z12: Maps MCP security controls and identifies coverage gaps concerning resource impersonation and trust placement. | AA12: Abstract screened | AB12: Not yet used
A13: N010 | B13: P3-MEDIUM | C13: Model Context Protocol Threat Modeling and Analyzing Vulnerabilities to Prompt Injection with Tool Poisoning | D13: Huang, C., Huang, X., Tran, N. P. and Milani Fard, A. (2026) 'Model Context Protocol Threat Modeling and Analyzing Vulnerabilities to Prompt Injection with Tool Poisoning', arXiv preprint, arXiv:2603.22489. https://doi.org/10.48550/arXiv.2603.22489. | E13: 2026 | F13: Preprint | G13: AI Agent Security | H13: =I13&" "&J13&" "&K13&" "&L13&" "&M13 -> RO1 | I13: RO1 | N13: Threat Modelling | O13: Empirical Study | P13: Enterprise AI (MCP) | Q13: LLM Agent | R13: Tool Poisoning; Identity Spoofing | S13: Trust | T13: Systematic threat model for MCP; tool poisoning and identity spoofing demonstrated | U13: ARXIV-S2 | V13: RO1: identifies "tool poisoning" as a critical pathway where malicious instructions are embedded directly into the metadata of the tools the agents rely on to interact with their environment. Main contribution: The authors provide a comparative empirical analysis of seven major Model Context Protocol (MCP) clients, demonstrating that the success of tool-poisoning attacks (ranging from 0% to 100%) depends on client-side validation and UI design rather than the underlying LLM's capabilities. It proves that current agent ecosystems lack standardized security, creating a significant "client-side exploitation" gap where malicious metadata can manipulate an agent’s reasoning process. Strongest citable concept/mechanism/model: Tool Poisoning — A specific form of indirect prompt injection where malicious instructions are embedded in tool metadata (names, descriptions, and parameter schemas) rather than user input to hijack an agent's decision-making. Limitation or questionable assumption: The authors admit that their DREAD severity scoring is subjective and potentially influenced by author bias. Furthermore, the study did not empirically verify "Execution Sandboxing" capabilities, relying instead on documentation and architectural analysis to classify this feature. Dissertation-ready note: This study highlights "approval fatigue" as a critical human-centric vulnerability, where users habitually approve agent requests without scrolling to inspect long or hidden parameters that may contain malicious instructions (Section 1.1,). It concludes that the human layer is currently an ineffective "trust boundary" because client interfaces fail to provide the transparency necessary for users to verify the true nature of an agent's intent (Section 4.2,). | W13: Eligible analytical source | X13: Structured database search | Y13: arXiv | Z13: Provides a threat model and empirical evidence of tool poisoning and identity-spoofing vulnerabilities in MCP environments. | AA13: Abstract screened | AB13: Not yet used
A14: N011 | B14: P3-MEDIUM | C14: Agentic AI Security: Threats, Defenses, Evaluation, and Open Challenges | D14: Chhabra, A., Datta, S., Nahin, S. K. and Mohapatra, P. (2025) 'Agentic AI Security: Threats, Defenses, Evaluation, and Open Challenges', IEEE Access , 14, pp. 1-35. https://doi.org/10.1109/ACCESS.2026.3675554 | E14: 2025 | F14: Journal Peer-reviewed | G14: Agentic AI Security | H14: =I14&" "&J14&" "&K14&" "&L14&" "&M14 -> RO1 | I14: RO1 | N14: Systematic Review | O14: Academic Literature | P14: Enterprise AI | Q14: Agentic AI | R14: Impersonation; Privilege Abuse | S14: Trust | T14: Comprehensive taxonomy of agentic AI threats; impersonation and trust exploitation are critical gaps | U14: GSLABS-01 | V14: RO(s) supported (from RO1–RO5): RO1 (Conceptualising autonomous AI agent impersonation as a threat) and RO3 (Examining how current literature addresses or fails to address the human–agent distinction). Main contribution: The authors provide a comprehensive taxonomy of agentic security that identifies "Human-Agent Security Interfaces" as a unique "security frontier" where technical robustness is undermined by human susceptibility to social engineering. It establishes that agent security is not merely an algorithmic problem but a "human factors" issue where attackers exploit user trust to subvert oversight. Strongest citable concept/mechanism/model: Human-Agent Security Interfaces — A conceptual model of the "interface layer" where the security of autonomous systems depends on the dynamic interaction between algorithmic robustness and human susceptibility to manipulation or "approval fatigue". Limitation or questionable assumption: The authors advocate for "human-in-the-loop" control as a primary safety measure while simultaneously admitting that such verification tasks often "overly burden" users, reduce automation efficiency, and are easily bypassed when attackers use "socially engineered" prompts to secure human approval. Dissertation-ready note: This source is a cornerstone for RO3 as it explicitly defines the boundary between humans and agents as a "security frontier" where traditional oversight fails due to the "complexity of long execution traces" and "user trust" (Section VI-G, p. 106). It justifies the need for entity-nature verification by arguing that the current security of agentic systems is fundamentally compromised by "human susceptibility" to deception (Section VI-G, p. 106). | W14: Eligible analytical source | X14: Targeted supplementary search | Y14: Google Scholar Labs | Z14: Synthesises agentic AI threats and defences, including impersonation, privilege abuse and trust exploitation. | AA14: Abstract screened | AB14: Not yet used
A15: N012 | B15: P1-CORE | C15: Securing Agentic AI: A Comprehensive Threat Model and Mitigation Framework for Generative AI Agents | D15: Narajala, V. S. and Narayan, O. (2025) 'Securing Agentic AI: A Comprehensive Threat Model and Mitigation Framework for Generative AI Agents', Preprint . Available at: https://arxiv.org/html/2504.19956v2 (Accessed: 12 April 2025). | E15: 2025 | F15: Preprint | G15: Agentic AI Security | H15: =I15&" "&J15&" "&K15&" "&L15&" "&M15 -> RO1 RO3 RO4 | I15: RO1 | K15: RO3 | L15: RO4 | N15: Threat Modelling | O15: Conceptual Analysis | P15: Enterprise AI | Q15: Generative AI Agents | R15: Impersonation; Prompt Injection | S15: Trust | T15: Threat model combining STRIDE and MAESTRO; agent impersonation ranked critical | U15: GSLABS-01 | V15: RO1: explains that unlike traditional chatbots, agentic systems possess persistent memory, subgoal decomposition, and external tool integration, allowing them to autonomously reason and act with minimal human oversight. RO3: This paper explicitly argues that existing standards such as the NIST AI Risk Management Framework, MITRE ATLAS, and OWASP Top 10 for LLMs fall short for GenAI agents because they do not adequately address agent-specific dynamics. Specifically, it evaluates how these frameworks struggle with entity nature (identity becomes fluid in multi-agent networks, blurring the lines between user and agent identity) and delegated authority (tool execution boundaries are difficult to manage using traditional role-based access controls). RO4: Explicitly outlines "Identity Spoofing & Trust Exploitation" (T6), noting that identity is fluid in MAS and creates ambiguity in attribution, allowing attackers to perform unauthorized operations under falsified contexts. Main contribution (1–2 sentences, don't just restate the abstract): The source establishes the Advanced Threat Framework for Autonomous AI Agents (ATFAA) and the SHIELD mitigation model, specifically targeting risks unique to agentic architecture like cognitive reasoning manipulation and temporal memory poisoning. It argues that agents fundamentally expand the attack surface beyond traditional LLMs through "Identity Fluidity" and the ability to traverse organizational boundaries autonomously. Strongest citable concept/mechanism/model: T7: Human-Agent Trust Manipulation — A threat model where attackers exploit the "human-AI trust interface" by using "trust amplification signals" (such as mimicking trusted communication styles) to induce humans into bypassing technical security controls. Limitation or questionable assumption: The authors acknowledge the framework is "primarily based on theoretical analysis" and literature review rather than "extensive empirical red teaming against live systems." Additionally, the SHIELD mitigation of "Escalation Control" assumes that frequent re-authentication is a viable defense, despite the authors elsewhere admitting this can create "usability friction" and "operational overhead" for users. Dissertation-ready note (max 2 sentences, in my own words, with page/section reference if possible): The source frames the human-agent boundary as a psychological "trust interface" where the "mimicking [of] trusted communication styles" can effectively nullify technical security layers (Section IV-A-6, p. 39). It explicitly identifies "Identity Fluidity" as a novel risk factor because the "blurry line" between agent and user identities creates impersonation opportunities that traditional authentication models cannot currently resolve (Section IV-D, p. 60). | W15: Eligible analytical source | X15: Structured database search | Y15: arXiv | Z15: Provides an agent-specific threat model covering identity fluidity, impersonation, delegated tool access and human–agent trust manipulation. | AA15: Abstract screened | AB15: Not yet used
A16: N013 | B16: P3-MEDIUM | C16: Securing Agentic AI: Threat Modeling and Risk Analysis for Network Monitoring Agentic AI System | D16: Zambare, P., Thanikella, V.N. and Liu, Y. 2025. 'Securing Agentic AI: Threat Modeling and Risk Analysis for Network Monitoring Agentic AI System'. arXiv preprint arXiv:2508.10043v1. Available at: https://arxiv.org/html/2508.10043v1 | E16: 2025 | F16: Preprint | G16: Agentic AI Security | H16: =I16&" "&J16&" "&K16&" "&L16&" "&M16 -> RO3 | K16: RO3 | N16: Threat Modelling | O16: Case Study | P16: Network Operations | Q16: Agentic AI | R16: Agent Identity Spoofing | S16: Trust | T16: Network monitoring agent threat model; agent impersonation enables silent surveillance bypass | U16: ARXIV-S3 | V16: RO3: this study evaluates established models like STRIDE, PASTA, and the OWASP Top 10, concluding that they are inadequate for agentic systems because they fail to cover the operational autonomy and dynamic reasoning stratums of AI agents | W16: Eligible analytical source | X16: Structured database search | Y16: arXiv | Z16: Applies established threat-modelling approaches to an agentic system and identifies their limitations concerning identity and operational autonomy. | AA16: Abstract screened | AB16: Not yet used
A17: N014 | B17: P4-SUPPORT | C17: Taming OpenClaw: Security Analysis and Mitigation of Autonomous LLM Agent Threats | D17: Deng, X., Zhang, Y., Wu, J., Bai, J., Yi, S., Zou, Z., Xiao, Y., Qiu, R., Ma, J., Chen, J., Du, X., Yang, X., Cui, S., Meng, C., Wang, W., Song, J., Xu, K., & Li, Q. (2026). Taming OpenClaw: Security Analysis and Mitigation of Autonomous LLM Agent Threats. ArXiv, abs/2603.11619. | E17: 2026 | F17: Preprint | G17: Agentic AI Security | H17: =I17&" "&J17&" "&K17&" "&L17&" "&M17 -> RO1 RO3 | I17: RO1 | K17: RO3 | N17: Security Analysis | O17: Empirical Study | P17: Enterprise AI | Q17: Autonomous LLM Agent | R17: Prompt Injection; Agent Hijacking | S17: Trust | T17: OpenClaw vulnerabilities; prompt injection enables full agent control/impersonation | U17: ARXIV-S3 | V17: RO1 and RO3: This paper analyzes systemic threats against autonomous LLMs, specifically highlighting "capability impersonation" where an agent's intended functions are silently hijacked via malicious skill injection. It also evaluates execution controls, permission frameworks, and sandboxing as measures to secure delegated authority and operational autonomy | W17: Eligible analytical source | X17: Structured database search | Y17: arXiv | Z17: Provides empirical evidence of agent hijacking through malicious skills and evaluates controls over delegated capabilities and execution. | AA17: Abstract screened | AB17: Not yet used
A18: N015 | B18: P2-HIGH | C18: ClawSafety: 'Safe' LLMs, Unsafe Agents | D18: Wei, B., Zhang, Y., Pan, J., Mei, K., Wang, X., Hamm, J., Zhu, Z. and Ge, Y. (2026) 'CLAWSAFETY: ”Safe” LLMs, Unsafe Agents'. Available at: https://arxiv.org/pdf/2604.01438 | E18: 2026 | F18: Preprint | G18: Agentic AI Security | H18: =I18&" "&J18&" "&K18&" "&L18&" "&M18 -> RO4 RO5 | L18: RO4 | M18: RO5 | N18: Empirical Evaluation | O18: Empirical Study | P18: Enterprise AI | Q18: Autonomous LLM Agent | R18: Safety Bypass; Impersonation | S18: Trust | T18: Safety-aligned LLMs remain exploitable as agents; agent context enables impersonation attacks | U18: ARXIV-S3 | V18: RO4: Demonstrates that AI agents themselves suffer from exploitable trust asymmetries when verifying entities. It shows that agents inherently grant higher trust to operational peers than organizational superiors based on role plausibility, and implicitly trust files with established workspace provenance without performing verification. RO5: Demonstrates empirically how agents calibrate trust based on the operational plausibility of a sender's role. It features a case where an agent successfully impersonates an "operational peer" (e.g., a Treasurer) rather than an executive to induce exfiltration, proving that verification must go beyond simple hierarchy. | W18: Eligible analytical source | X18: Structured database search | Y18: arXiv | Z18: Provides empirical evidence that safety-aligned models can become vulnerable when configured as agents and granted access to operational context and tools. | AA18: Abstract screened | AB18: Not yet used
A19: N016 | B19: P3-MEDIUM | C19: Automating Agent Hijacking via Structural Template Injection | D19: Deng, X., Wu, J., Chen, M., Xiao, Y., Xu, K. and Li, Q. (2026) 'Automating Agent Hijacking via Structural Template Injection', USA: ACM. Available at: https://arxiv.org/pdf/2602.16958 | E19: 2026 | F19: Preprint | G19: Agentic AI Security | H19: =I19&" "&J19&" "&K19&" "&L19&" "&M19 -> RO1 | I19: RO1 | N19: Attack Demonstration | O19: Empirical Study | P19: Enterprise AI | Q19: LLM Agent | R19: Agent Hijacking / Impersonation | S19: Trust | T19: Automated template injection hijacks agent sessions; enables persistent impersonation at scale | U19: ARXIV-S3 | V19: Focuses on a specific attack pathway called "role confusion." By injecting malicious payloads into retrieved content, attackers can force the agent to treat attacker-controlled text as legitimate user instructions or forged assistant responses, effectively subverting the agent's identity and operational flow | W19: Eligible analytical source | X19: Structured database search | Y19: arXiv | Z19: Demonstrates how structural template injection can create role confusion and hijack an agent's operational context. | AA19: Abstract screened | AB19: Not yet used
A20: N017 | B20: P3-MEDIUM | C20: Progent: Securing AI Agents with Privilege Control | D20: Shi, T., He, J., Wang, Z., Li, H., Wu, L., Guo, W. and Song, D. (2025) 'Progent: Securing AI Agents with Privilege Control'. arXiv preprint, arXiv:2504.11703.. Available at: https://arxiv.org/pdf/2504.11703 (Accessed: 13 April 2026). | E20: 2025 | F20: Preprint | G20: AI Agent Security | H20: =I20&" "&J20&" "&K20&" "&L20&" "&M20 -> RO5 | M20: RO5 | N20: Framework Proposal | O20: Empirical Study | P20: Enterprise AI | Q20: LLM Agent | R20: Privilege Escalation; Identity Boundary | S20: Trust | T20: Least-privilege model for LLM agents; privilege escalation as proxy for identity boundary violation | U20: ARXIV-S3 | V20: RO5: Focuses on managing the delegated authority of AI agents through formal privilege control. It proposes deterministic enforcement at the tool-call level to prevent silent privilege escalation | W20: Eligible analytical source | X20: Structured database search | Y20: arXiv | Z20: Evaluates deterministic privilege controls for limiting the authority delegated to LLM agents at the tool-call level. | AA20: Abstract screened | AB20: Not yet used
A21: N018 | B21: P3-MEDIUM | C21: The Landscape of Prompt Injection Threats in LLM Agents: From Taxonomy to Analysis | D21: Wang, P., Li, X., Xiang, C., Zhang, J., Li, Y., Zhang, L., Wang, X. and Tian, Y. (2026) 'The Landscape of Prompt Injection Threats in LLM Agents: From Taxonomy to Analysis', arXiv preprint . Available at: https://arxiv.org/pdf/2602.10453 (Accessed: 20 October 2025). | E21: 2026 | F21: Preprint | G21: AI Agent Security | H21: =I21&" "&J21&" "&K21&" "&L21&" "&M21 -> RO1 | I21: RO1 | N21: Taxonomy / Empirical | O21: Academic Literature | P21: Enterprise AI | Q21: LLM Agent | R21: Prompt Injection as Impersonation Vector | S21: Trust | T21: Taxonomy of 12 prompt injection variants; indirect injection enables agent impersonation in org messaging | U21: ARXIV-S3 | V21: RO1: maps out Indirect Prompt Injection (IPI) pathways, where adversarial instructions embedded in external resources—such as incoming emails or web pages—successfully hijack the agent’s execution loop to perform unauthorized tasks. Main contribution: The authors provide a comprehensive systematisation of the prompt injection (PI) landscape, identifying a critical "evaluation gap" where current defenses fail against "context-dependent" tasks that manipulate an agent's reasoning logic rather than just overriding commands. It introduces the AGENTPI benchmark to empirically demonstrate that procedurally valid tool calls can be triggered by corrupting an agent’s internal reasoning through poisoned environmental feedback. Strongest citable concept/mechanism/model: Delegation Exploitation — A context-aware attack vector where an adversary hijacks an agent's trust chain by embedding malicious instructions within a specific data source that the user has explicitly authorized the agent to process, thereby bypassing intent-alignment defenses. Limitation or questionable assumption: The authors acknowledge that the "intent alignment" paradigm relies on the assumption that user intent is ground truth and can be precisely defined, yet they admit that "vague" or "mis-authorized" prompts from users create vulnerabilities that technical filters cannot resolve. Additionally, they note that involving humans as "intent aligners" to specify security policies creates high latency and contradicts the goal of full automation. Dissertation-ready note: This source is vital for RO3 as it argues that current security evaluations suffer from a "false sense of security" by focusing on binary action success while remaining "blind" to the integrity of the agent's internal reasoning process (Section 5, p. 10; Section 7.2, p. 12). It defines a novel "Untrusted-to-Trusted Data" invasion where agents promote deceptive environmental observations—often indistinguishable from benign data to a human—into trusted execution parameters, effectively "impersonating" a legitimate logical deduction (Appendix D4, p. 19; Appendix D5, p. 19). | W21: Eligible analytical source | X21: Structured database search | Y21: arXiv | Z21: Classifies prompt-injection pathways through which external text can impersonate instructions and redirect agent actions. | AA21: Abstract screened | AB21: Not yet used
A22: N019 | B22: P3-MEDIUM | C22: Securing GenAI Multi-Agent Systems Against Tool Squatting: A Zero Trust Registry-Based Approach | D22: Narajala, V.S., Huang, K. and Habler, I. (2026) ‘Securing GenAI multi-agent systems against tool squatting: A zero trust registry-based approach’, in 2026 International Conference on AI x Data and Knowledge Engineering (AIxDKE). Laguna Hills, CA: IEEE, pp. 91–93. https://doi.org/10.1109/AIxDKE67294.2026.00022. | E22: 2025 | F22: Conference Paper | G22: AI Agent Security | H22: =I22&" "&J22&" "&K22&" "&L22&" "&M22 -> RO4 | L22: RO4 | N22: Framework Proposal | O22: Conceptual Analysis | P22: Enterprise AI | Q22: Multi-Agent GenAI | R22: Tool Squatting / Tool Impersonation | S22: Trust | T22: Proposes a zero-trust registry that separates agent and tool identities and uses policy controls, dynamic trust scoring and scoped just-in-time credentials to address tool squatting. | U22: IEEE-S6 | V22: RO4: Explores "Tool Squatting," where malicious actors deceptively register tools to misrepresent their capabilities, exploiting discovery mechanisms lacking a verified source of truth | W22: Eligible analytical source | X22: Structured database search | Y22: IEEE Xplore | Z22: Examines tool squatting and proposes a verified registry for reducing deceptive tool identity and discovery. | AA22: Abstract screened | AB22: Not yet used
A23: N020 | B23: P3-MEDIUM | C23: Security Threat Modelling for Emerging AI-Agent Protocols: MCP, A2A, Agora, ANP | D23: Anbiaee, Z., Rabbani, M., Mirani, M., Piya, G., Opushnyev, I., Ghorbani, A. and Dadkhah, S. (2026) ‘Security Threat Modeling for Emerging AI-Agent Protocols: A Comparative Analysis of MCP, A2A, Agora, and ANP’, arXiv preprint, arXiv:2602.11327. Available at: https://arxiv.org/abs/2602.11327 (Accessed: 20 July 2026). | E23: 2026 | F23: Preprint | G23: AI Agent Security | H23: =I23&" "&J23&" "&K23&" "&L23&" "&M23 -> RO4 | L23: RO4 | N23: Comparative Threat Modelling | O23: Conceptual Analysis | P23: Agent Communication Protocols | Q23: Multi-Agent | R23: Impersonation via Protocol Vulnerabilities | S23: Trust | T23: Comparative threat modelling identifies identity-binding and authority risks across four protocols. A controlled MCP case demonstrates wrong-provider selection under specified ordering and metadata conditions. | U23: ARXIV-S2 | V23: RO4: Highlights the lack of identity binding validation in multi-agent protocols. It empirically demonstrates how a lack of resolution in ambiguity between tools and providers leads to "tool identity ambiguity attacks," causing clients to invoke wrong-provider or poisoned tools, culminating in systemic integrity loss. Violation rate was 1.00 under attacker-first ordering and persuasive trust-cue metadata, and 0.52 when metadata was cloned. | W23: Eligible analytical source | X23: Structured database search | Y23: arXiv | Z23: Compares four agent protocols and identifies recurring identity-binding and impersonation weaknesses. | AA23: Full text reviewed | AB23: Analytical contribution
A24: N021 | B24: P1-CORE | C24: Open Challenges in Multi-Agent Security: Towards Secure Systems of Interacting AI Agents | D24: Schroeder de Witt, C., Krawiecka, K., Krawczuk, I., Hagag, B., Anderson, W. L., Belcak, P., Bucknall, B., Cai, X., Chopra, A., Cohen, D., Del Rosario, R. F., Draguns, A., Gray, A., Katz, K., Mavroudis, V., Mink, J., Motwani, S. R., Petit, J., Rembeck, L.-S., Smith, C., Sotiropoulos, J., Young, S., Scheffler, S. and Llewellyn, M. (2026) 'Open Challenges in Multi-Agent Security: Towards Secure Systems of Interacting AI Agents', v1.0. https://arxiv.org/html/2505.02077v2 (Accessed: 22 May 2025). | E24: 2026 | F24: Preprint | G24: AI Agent Security | H24: =I24&" "&J24&" "&K24&" "&L24&" "&M24 -> RO1 RO3 RO4 RO5 | I24: RO1 | K24: RO3 | L24: RO4 | M24: RO5 | N24: Conceptual Analysis | O24: Academic Literature | P24: Multi-Agent Systems | Q24: Multi-Agent | R24: Steganographic Impersonation; Coordination Attacks | S24: Trust | T24: Ten open security challenges; steganographic communication and agent impersonation highlighted | U24: GSLABS-02 | V24: RO1: investigates advanced manipulation techniques, including "role hijacking" (where an agent is prompted to assume a privileged identity), "dark patterns" designed to exploit human cognitive limitations, and emergent steganographic collusion between agents to hide deceptive intents. RO3:This paper discusses how traditional privacy primitives and access control frameworks (like RBAC and ABAC) fail to map properly to entity nature and delegated authority in multi-agent ecosystems. It highlights that these frameworks were designed for human roles rather than dynamically spawned, short-lived agents, which creates fundamental problems for auditing and attribution. RO4: Examines covert collusion, steganography, and how agents exploit information asymmetries to covertly manipulate shared environments or deceive other agents' decision processes. RO5: Examines the security implications of agents dynamically delegating tasks. It emphasizes applying the "least-privilege principle" alongside robust access control and authentication to prevent compromised agents from propagating unauthorized access. Main contribution (1–2 sentences, don't just restate the abstract): The source formalises Multi-Agent Security (MASEC) as a distinct discipline, arguing that security in agentic ecosystems is non-compositional, meaning that individually "safe" agents can interact to produce unsafe emergent behaviours that are structurally difficult to observe or predict. It identifies the "sociotechnical interface" as a primary exploit surface where coordinated agent interactions can bypass human oversight through deceptive social engineering. Strongest citable concept/mechanism/model: Illusion of Independent Corroboration — A sociotechnical threat where coordinated fleets of agents converge on a shared narrative to simulate a consensus, effectively manipulating human trust and perception by making a deceptive message appear as if it is being validated by multiple autonomous entities. Limitation or questionable assumption: The authors adopt an "anticipatory posture" which, while proactive, means the framework primarily characterises threats that are "structurally enabled" but "not yet widely observed in practice," potentially limiting its immediate empirical applicability. Furthermore, they admit that simple defensive strategies like paraphrasing fail to remove the underlying semantic entropy that enables covert agent collusion. Dissertation-ready note (max 2 sentences, in my own words, with page/section reference if possible): This source is critical for RO3 because it defines the "sociotechnical interface" as a zone where agents can weaponise "synthetic gaze," "proxemics," and "affective nudging" to distort human perception (Section 3.2.10). It provides evidence that entity-nature verification is hindered by the ability of agents to hide malicious coordination within "syntactically and semantically valid" communication that remains statistically indistinguishable from benign human interaction (Section 4.3). | W24: Eligible analytical source | X24: Structured database search | Y24: arXiv | Z24: Identifies security mechanisms and emergent risks in multi-agent systems, including role hijacking, covert coordination, delegation and failures of conventional access control. | AA24: Abstract screened | AB24: Not yet used
A25: N022 | B25: P4-SUPPORT | C25: Architecture Matters for Multi-Agent Security | D25: Hagag, B., Anderson, W. L., Schroeder de Witt, C. and Scheffler, S. (2026) ‘Architecture Matters for Multi-Agent Security’, arXiv preprint, arXiv:2604.23459. Available at: https://arxiv.org/abs/2604.23459 (Accessed: 20 July 2026). | E25: 2026 | F25: Preprint | G25: AI Agent Security | H25: =I25&" "&J25&" "&K25&" "&L25&" "&M25 -> RO1 | I25: RO1 | N25: Empirical Evaluation | O25: Empirical Study | P25: Multi-Agent Systems | Q25: Multi-Agent | R25: Impersonation via Architectural Weakness | S25: Trust | T25: Centralised vs. decentralised agent architectures differ in impersonation exposure; design implications | U25: ARXIV-S3 | V25: RO1: This study explores how multi-agent system architectures can fragment safety responsibilities and increase vulnerability to deception. It demonstrates how agents can be exploited to execute malicious text-based organizational communication, such as generating phishing emails to impersonate a trusted vendor | W25: Eligible analytical source | X25: Structured database search | Y25: arXiv | Z25: Demonstrates how multi-agent architecture affects exposure to deception, impersonation and fragmented security responsibility. | AA25: Abstract screened | AB25: Not yet used
A26: N023 | B26: P3-MEDIUM | C26: When Agents Handle Secrets: Confidential Computing for Agentic AI | D26: Forough, J., Kogias, M. and Haddadi, H. (2026) ‘When Agents Handle Secrets: A Survey of Confidential Computing for Agentic AI’, arXiv preprint, arXiv:2605.03213. Available at: https://arxiv.org/abs/2605.03213 (Accessed: 20 July 2026). | E26: 2026 | F26: Preprint (Survey) | G26: AI Agent Security | H26: =I26&" "&J26&" "&K26&" "&L26&" "&M26 -> RO5 | M26: RO5 | N26: Systematic Review | O26: Academic Literature | P26: Enterprise AI | Q26: Agentic AI | R26: Secret Exfiltration; Identity Boundary Breach | S26: Trust | T26: Survey of confidential computing for agents; rogue agent impersonation enables pipeline poisoning | U26: ARXIV-S3 | V26: RO5: Specifically treats "delegation structure and coordination policy as first-class analytical dimensions." It explores how confidential computing and Trusted Execution Environments (TEEs) can protect delegation chains, partial provenance, and agent-to-tool message authenticity | W26: Eligible analytical source | X26: Structured database search | Y26: arXiv | Z26: Synthesises confidentiality, provenance and message-authenticity controls relevant to agent delegation structures. | AA26: Abstract screened | AB26: Not yet used
A27: N024 | B27: P2-HIGH | C27: Multi-Agent Systems Execute Arbitrary Malicious Code via Agent Communication Poisoning | D27: Triedman, H., Jha, R. and Shmatikov, V. (2025) ‘Multi-Agent Systems Execute Arbitrary Malicious Code’, arXiv preprint, arXiv:2503.12188. Available at: https://arxiv.org/abs/2503.12188 (Accessed: 20 July 2026). | E27: 2025 | F27: Conference Paper | G27: AI Agent Security | H27: =I27&" "&J27&" "&K27&" "&L27&" "&M27 -> RO1 RO4 | I27: RO1 | L27: RO4 | N27: Attack Demonstration | O27: Empirical Study | P27: Multi-Agent Communication | Q27: Multi-Agent LLM | R27: Communication Poisoning / Impersonation | S27: Trust | T27: Communication poisoning enables arbitrary code execution via compromised agent identity | U27: ARXIV-S3 | V27: RO1: Multi-Agent Systems Execute Arbitrary Malicious Code demonstrates "MAS hijacking," an attack pathway where malicious text (like a processed email attachment) turns sub-agents into "confused deputies," allowing adversaries to orchestrate unauthorized code execution or data exfiltration. RO4: Discusses the "confused deputy problem," where LLMs blindly trust the outputs of other sub-agents without verifying the semantics or nature of the inputs, laundering malicious requests into trusted enterprise workflows. | W27: Eligible analytical source | X27: Structured database search | Y27: arXiv | Z27: Demonstrates how malicious textual inputs can propagate through multi-agent communication and cause unauthorised tool execution through confused-deputy behaviour. | AA27: Abstract screened | AB27: Not yet used
